Workbook

Sheet 01.07.26
A1: CONTA: 200000 AGÊNCIA: 3309
A3: SALDO INICIAL: | B3: 199998.3
A4: Recebimentos | B4: =SUM(B5:B18) -> 3698871.9 | C4: SITUAÇÃO | D4: NÚMERO DO RECEBIMENTO | E4: TIPO DE SERVIÇO
A5: Transferência recebida: 553.307.000.036.846 01/07 15:11 BB CONSORCIOS ADMINISTRA | B5: 3698870.2 | C5: VALOR LANÇADO | D5: 0107001-GYN | E5: COBAN CONSORCIOS
A6: Transferência recebida: 553.309.000.205.826 01/07 12:12 BB TECNOLOGIA E SERVICOS | B6: 1.7 | C6: VALOR LANÇADO | E6: TRANSFERÊNCIA | G6: NOTA FISCAL | H6: VALOR BRUTO NF | I6: IR 1,5% | J6: VALOR LIQUIDO
G7: 114 | H7: 3755198.2 | I7: =H7*1.5% -> 56327.973 | J7: =H7-I7 -> 3698870.2
G12: NOTA FISCAL | H12: VALOR BRUTO NF | I12: IR | J12: PIS | K12: COFINS | L12: CSLL | M12: ISS | N12: VALOR LIQUIDO
I13: =H13*4.8% -> 0 | J13: =H13*0.65% -> 0 | K13: =H13*3% -> 0 | L13: =H13*1% -> 0 | M13: =H13*2% -> 0 | N13: =H13-I13-J13-K13-L13-M13 -> 0
A19: Pagamentos | B19: =SUM(B20:B32) -> 0 | C19: SITUAÇÃO | D19: NÚMERO DO RECEBIMENTO | E19: TIPO DE SERVIÇO
A33: SALDO FINAL: | B33: =B3+B4-B19 -> 3898870.2

Sheet 02.07.26
A1: CONTA: 200000 AGÊNCIA: 3309
A3: SALDO INICIAL: | B3: ='01.07.26'!B33 -> 3898870.2
A4: Recebimentos | B4: =SUM(B5:B18) -> 0 | C4: SITUAÇÃO | D4: NÚMERO DO RECEBIMENTO | E4: TIPO DE SERVIÇO
A19: Pagamentos | B19: =SUM(B20:B32) -> 3698944.9 | C19: SITUAÇÃO | D19: NÚMERO DO RECEBIMENTO | E19: TIPO DE SERVIÇO
A20: Transferência enviada 553.309.000.205.826 02/07 10:19 BB TEC 00042318949000184 | B20: 3698870.2 | C20: VALOR LANÇADO | E20: TRANSFERÊNCIA
A21: Tar Manuten Conta Ativa 811.830.700.083.461 Cobrança referente 02/07/2026 | B21: 73 | C21: VALOR LANÇADO | D21: 02-JUL-26001001200000/2 | E21: TARIFAS
A22: Tarifa Transf Recurso-E/I 821.831.100.029.494 | B22: 1.7 | C22: VALOR LANÇADO | D22: 02-JUL-26001001200000/3 | E22: TARIFAS
A33: SALDO FINAL: | B33: =B3+B4-B19 -> 199925.3

Sheet 03.07.26
A1: CONTA: 200000 AGÊNCIA: 3309
A3: SALDO INICIAL: | B3: ='02.07.26'!B33 -> 199925.3
A4: Recebimentos | B4: =SUM(B5:B18) -> 200000 | C4: SITUAÇÃO | D4: NÚMERO DO RECEBIMENTO | E4: TIPO DE SERVIÇO | G4: NOTA FISCAL | H4: VALOR BRUTO NF | I4: IR | J4: PIS | K4: COFINS | L4: CSLL | M4: ISS | N4: VALOR LIQUIDO
A5: Transferência recebida 553.309.000.205.826 03/07 13:28 BB TECNOLOGIA E SERVICOS | B5: 200000 | C5: VALOR LANÇADO | D5: 03-JUL-26001001200000/2 | E5: Transferências | I5: =H5*4.8% -> 0 | J5: =H5*0.65% -> 0 | K5: =H5*3% -> 0 | L5: =H5*1% -> 0 | M5: =H5*2% -> 0 | N5: =H5-I5-J5-K5-L5-M5 -> 0
A19: Pagamentos | B19: =SUM(B20:B32) -> 199925.3 | C19: SITUAÇÃO | D19: NÚMERO DO RECEBIMENTO | E19: TIPO DE SERVIÇO
A20: Transferência enviada 553.309.000.205.826 03/07 09:24 BB TEC 00042318949000184 | B20: 199925.3 | C20: VALOR LANÇADO | D20: 03-JUL-26001001200000/1 | E20: Transferências
A33: SALDO FINAL: | B33: =B3+B4-B19 -> 200000

Sheet 06.07.26
A1: CONTA: 200000 AGÊNCIA: 3309
A3: SALDO INICIAL: | B3: ='03.07.26'!B33 -> 200000
A4: Recebimentos | B4: =SUM(B5:B18) -> 32822.04 | C4: SITUAÇÃO | D4: NÚMERO DO RECEBIMENTO | E4: TIPO DE SERVIÇO | G4: NOTA FISCAL | H4: VALOR BRUTO NF | I4: ISS 2% | J4: VALOR LIQUIDO
A5: Transferência recebida 553.309.000.205.826 06/07 11:52 BB TECNOLOGIA E SERVICOS | B5: 32822.04 | C5: VALOR LANÇADO | D5: 04-JUL-26001001200000/ | E5: TRANSFERÊNCIAS | I5: =H5*2% -> 0 | J5: =H5-I5 -> 0
A6: Bloq Judicial-Bacen Jud 12.637.588.550.401 | B6: 32822,04* | C6: VALORES BLOQUEADOS NÃO AFETA O SALDO
A19: Pagamentos | B19: =SUM(B20:B32) -> 32822.04 | C19: SITUAÇÃO | D19: NÚMERO DO RECEBIMENTO | E19: TIPO DE SERVIÇO
A20: Bloq Judicial-Bacen Jud 12.637.588.550.401 | B20: 32822.04 | C20: VALOR LANÇADO | D20: 06-JUL-26001001200000/2 | E20: BLOQ/DESBL/ALVARA JUD TRAB
A33: SALDO FINAL: | B33: =B3+B4-B19 -> 200000

Sheet 07.07.26
A1: CONTA: 200000 AGÊNCIA: 3309
A3: SALDO INICIAL: | B3: ='06.07.26'!B33 -> 200000
A4: Recebimentos | B4: =SUM(B5:B18) -> 0 | C4: SITUAÇÃO | D4: NÚMERO DO RECEBIMENTO | E4: TIPO DE SERVIÇO | G4: NOTA FISCAL | H4: VALOR BRUTO NF | I4: IR | J4: PIS | K4: COFINS | L4: CSLL | M4: ISS | N4: VALOR LIQUIDO
J5: =H5*0.65% -> 0 | K5: =H5*3% -> 0 | L5: =H5*1% -> 0 | N5: =H5-I5-J5-K5-L5-M5 -> 0
A19: Pagamentos | B19: =SUM(B20:B36) -> 0 | C19: SITUAÇÃO | D19: NÚMERO DO RECEBIMENTO | E19: TIPO DE SERVIÇO
A37: SALDO FINAL: | B37: =B3+B4-B19 -> 200000

Sheet 08.07.26
A1: CONTA: 200000 AGÊNCIA: 3309
A3: SALDO INICIAL: | B3: ='07.07.26'!B37 -> 200000
A4: Recebimentos | B4: =SUM(B5:B13) -> 0 | C4: SITUAÇÃO | D4: NÚMERO DO RECEBIMENTO | E4: TIPO DE SERVIÇO | G4: NOTA FISCAL | H4: VALOR BRUTO NF | I4: IR 4,8% | J4: PIS 0,65% | K4: COFINS 3% | L4: CSLL 1% | M4: ISS 2% | N4: VALOR LIQUIDO
I5: =H5*4.8% -> 0 | J5: =H5*0.65% -> 0 | K5: =H5*3% -> 0 | L5: =H5*1% -> 0 | M5: =H5*2% -> 0 | N5: =H5-I5-J5-K5-L5-M5 -> 0
J9: =H9*0.65% -> 0 | K9: =H9*3% -> 0 | L9: =H9*1% -> 0 | N9: =H9-I9-J9-K9-L9-M9 -> 0
A28: SALDO FINAL: | B28: =B3+B4-B15 -> 200000

Sheet 09.07.26
A1: CONTA: 200000 AGÊNCIA: 3309
A3: SALDO INICIAL: | B3: ='08.07.26'!B28 -> 200000
A4: Recebimentos | B4: =SUM(B5:B18) -> 0 | C4: SITUAÇÃO | D4: NÚMERO DO RECEBIMENTO | E4: TIPO DE SERVIÇO
G5: NOTA FISCAL | H5: VALOR NF
G10: NOTA FISCAL | H10: VALOR BRUTO NF | I10: IR | J10: PIS | K10: COFINS | L10: CSLL | M10: ISS | N10: VALOR LIQUIDO
I11: =H11*1.5% -> 0 | J11: =0.65%*H11 -> 0 | K11: =3%*H11 -> 0 | L11: =1%*H11 -> 0 | M11: =H11*1.2574% -> 0 | N11: =H11-I11-J11-K11-L11-M11 -> 0
G13: NOTA FISCAL | H13: VALOR BRUTO NF | I13: IR | J13: PIS | K13: COFINS | L13: CSLL | M13: ISS | N13: VALOR LIQUIDO
I14: =H14*4.8% -> 0 | J14: =0.65%*H14 -> 0 | K14: =3%*H14 -> 0 | L14: =1%*H14 -> 0 | N14: =H14-I14-J14-K14-L14-M14 -> 0
I15: =H15*4.8% -> 0 | J15: =0.65%*H15 -> 0 | K15: =3%*H15 -> 0 | L15: =1%*H15 -> 0 | N15: =H15-I15-J15-K15-L15-M15 -> 0
I16: =H16*4.8% -> 0 | J16: =0.65%*H16 -> 0 | K16: =3%*H16 -> 0 | L16: =1%*H16 -> 0 | M16: =H16*5% -> 0 | N16: =H16-I16-J16-K16-L16-M16 -> 0
G17: TOTAL | H17: =SUM(H14:H16) -> 0 | I17: =SUM(I14:I16) -> 0 | J17: =SUM(J14:J16) -> 0 | K17: =SUM(K14:K16) -> 0 | L17: =SUM(L14:L16) -> 0 | M17: =SUM(M14:M16) -> 0 | N17: =SUM(N14:N16) -> 0
A19: Pagamentos | B19: =SUM(B20:B32) -> 0 | C19: SITUAÇÃO | D19: NÚMERO DO RECEBIMENTO | E19: TIPO DE SERVIÇO
A33: SALDO FINAL: | B33: =B3+B4-B19 -> 200000
A37: 20833.33

Sheet 10.07.26
A1: CONTA: 200000 AGÊNCIA: 3309 | G1: 30054.26
G2: Tarifa bancária: R$ 9,00 por parcela
A3: SALDO INICIAL: | B3: ='09.07.26'!B33 -> 200000 | G3: Valor líquido por parcela: R$ 30.045,26
A4: Recebimentos | B4: =SUM(B5:B18) -> 10309479 | C4: SITUAÇÃO | D4: NÚMERO DO RECEBIMENTO | E4: TIPO DE SERVIÇO
A5: Crédito Sistema CDA 94.879.453 Pgt.BB Con202485580047/0018 / 1 | B5: 10279416 | C5: VALOR LANÇADO | D5: 1007001-GYN | E5: MANUT ALARME BB | G5: NOTA FISCAL | H5: VALOR BRUTO NF | I5: IR | J5: PIS | K5: COFINS | L5: CSLL | M5: ISS | N5: VALOR LIQUIDO
A6: Pix - Recebido 101.516.215.505.541 10/07 15:16 06105781000165 ZOOMTECH LT | B6: 30054.26 | C6: VALOR LANÇADO | D6: 1007002-GYN | E6: SERV INST SWITCHES | G6: 966 | H6: 881234.69 | I6: =H6*4.8% -> 42299.265 | J6: =H6*0.65% -> 5728.0255 | K6: =H6*3% -> 26437.041 | L6: =H6*1% -> 8812.3469 | N6: =H6-I6-J6-K6-L6-M6 -> 797958.01
B7: 9 | C7: TARIFAS VERIFICAR EMAIL PARCELAMENTO ZOOMTECH | G7: 1415 | H7: 400282.4 | I7: =H7*4.8% -> 19213.555 | J7: =H7*0.65% -> 2601.8356 | K7: =H7*3% -> 12008.472 | L7: =H7*1% -> 4002.824 | N7: =H7-I7-J7-K7-L7-M7 -> 362455.71
G8: 50 | H8: 612154 | I8: =H8*4.8% -> 29383.392 | J8: =H8*0.65% -> 3979.001 | K8: =H8*3% -> 18364.62 | L8: =H8*1% -> 6121.54 | N8: =H8-I8-J8-K8-L8-M8 -> 554305.45
G9: 1348 | H9: 486806.21 | I9: =H9*4.8% -> 23366.698 | J9: =H9*0.65% -> 3164.2404 | K9: =H9*3% -> 14604.186 | L9: =H9*1% -> 4868.0621 | N9: =H9-I9-J9-K9-L9-M9 -> 440803.02
G10: 1264 | H10: 217441.11 | I10: =H10*4.8% -> 10437.173 | J10: =H10*0.65% -> 1413.3672 | K10: =H10*3% -> 6523.2333 | L10: =H10*1% -> 2174.4111 | N10: =H10-I10-J10-K10-L10-M10 -> 196892.93
G11: 1140 | H11: 245978.26 | I11: =H11*4.8% -> 11806.956 | J11: =H11*0.65% -> 1598.8587 | K11: =H11*3% -> 7379.3478 | L11: =H11*1% -> 2459.7826 | N11: =H11-I11-J11-K11-L11-M11 -> 222733.31
G12: 64 | H12: 469083.41 | I12: =H12*4.8% -> 22516.004 | J12: =H12*0.65% -> 3049.0422 | K12: =H12*3% -> 14072.502 | L12: =H12*1% -> 4690.8341 | N12: =H12-I12-J12-K12-L12-M12 -> 424755.03
G13: 56 | H13: 232152.42 | I13: =H13*4.8% -> 11143.316 | J13: =H13*0.65% -> 1508.9907 | K13: =H13*3% -> 6964.5726 | L13: =H13*1% -> 2321.5242 | N13: =H13-I13-J13-K13-L13-M13 -> 210214.02
G14: 1226 | H14: 404171.79 | I14: =H14*4.8% -> 19400.246 | J14: =H14*0.65% -> 2627.1166 | K14: =H14*3% -> 12125.154 | L14: =H14*1% -> 4041.7179 | N14: =H14-I14-J14-K14-L14-M14 -> 365977.56
G15: 68 | H15: 437978.39 | I15: =H15*4.8% -> 21022.963 | J15: =H15*0.65% -> 2846.8595 | K15: =H15*3% -> 13139.352 | L15: =H15*1% -> 4379.7839 | N15: =H15-I15-J15-K15-L15-M15 -> 396589.43
G16: 69 | H16: 369750.16 | I16: =H16*4.8% -> 17748.008 | J16: =H16*0.65% -> 2403.376 | K16: =H16*3% -> 11092.505 | L16: =H16*1% -> 3697.5016 | N16: =H16-I16-J16-K16-L16-M16 -> 334808.77
G17: 1000900 | H17: 245762.48 | I17: =H17*4.8% -> 11796.599 | J17: =H17*0.65% -> 1597.4561 | K17: =H17*3% -> 7372.8744 | L17: =H17*1% -> 2457.6248 | N17: =H17-I17-J17-K17-L17-M17 -> 222537.93
G18: 1194 | H18: 430684.92 | I18: =H18*4.8% -> 20672.876 | J18: =H18*0.65% -> 2799.452 | K18: =H18*3% -> 12920.548 | L18: =H18*1% -> 4306.8492 | N18: =H18-I18-J18-K18-L18-M18 -> 389985.2
A19: Pagamentos | B19: =SUM(B20:B32) -> 10279416 | C19: SITUAÇÃO | D19: NÚMERO DO RECEBIMENTO | E19: TIPO DE SERVIÇO | G19: 42 | H19: 278383.73 | I19: =H19*4.8% -> 13362.419 | J19: =H19*0.65% -> 1809.4942 | K19: =H19*3% -> 8351.5119 | L19: =H19*1% -> 2783.8373 | N19: =H19-I19-J19-K19-L19-M19 -> 252076.47
A20: Transferência enviada 553.309.000.205.826 10/07 11:09 BB TEC 00042318949000184 | B20: 10279416 | C20: VALOR LANÇADO | E20: TRANSFERÊNCIA | F20: 883 | G20: 998 | H20: 350328.33 | I20: =H20*4.8% -> 16815.76 | J20: =H20*0.65% -> 2277.1341 | K20: =H20*3% -> 10509.85 | L20: =H20*1% -> 3503.2833 | N20: =H20-I20-J20-K20-L20-M20 -> 317222.3
G21: 202600050 | H21: 146468.24 | I21: =H21*4.8% -> 7030.4755 | J21: =H21*0.65% -> 952.04356 | K21: =H21*3% -> 4394.0472 | L21: =H21*1% -> 1464.6824 | N21: =H21-I21-J21-K21-L21-M21 -> 132626.99
G22: 18 | H22: 193540.61 | I22: =H22*4.8% -> 9289.9493 | J22: =H22*0.65% -> 1258.014 | K22: =H22*3% -> 5806.2183 | L22: =H22*1% -> 1935.4061 | N22: =H22-I22-J22-K22-L22-M22 -> 175251.02
G23: 202600000050 | H23: 174977.45 | I23: =H23*4.8% -> 8398.9176 | J23: =H23*0.65% -> 1137.3534 | K23: =H23*3% -> 5249.3235 | L23: =H23*1% -> 1749.7745 | N23: =H23-I23-J23-K23-L23-M23 -> 158442.08
G24: 883 | H24: 207981.86 | I24: =H24*4.8% -> 9983.1293 | J24: =H24*0.65% -> 1351.8821 | K24: =H24*3% -> 6239.4558 | L24: =H24*1% -> 2079.8186 | N24: =H24-I24-J24-K24-L24-M24 -> 188327.57
G25: 493 | H25: 467234.2 | I25: =H25*4.8% -> 22427.242 | J25: =H25*0.65% -> 3037.0223 | K25: =H25*3% -> 14017.026 | L25: =H25*1% -> 4672.342 | N25: =H25-I25-J25-K25-L25-M25 -> 423080.57
G26: 65 | H26: 593561.53 | I26: =H26*4.8% -> 28490.953 | J26: =H26*0.65% -> 3858.1499 | K26: =H26*3% -> 17806.846 | L26: =H26*1% -> 5935.6153 | N26: =H26-I26-J26-K26-L26-M26 -> 537469.97
G27: 1114 | H27: 511767.2 | I27: =H27*4.8% -> 24564.826 | J27: =H27*0.65% -> 3326.4868 | K27: =H27*3% -> 15353.016 | L27: =H27*1% -> 5117.672 | N27: =H27-I27-J27-K27-L27-M27 -> 463405.2
G28: 1104 | H28: 298946.26 | I28: =H28*4.8% -> 14349.42 | J28: =H28*0.65% -> 1943.1507 | K28: =H28*3% -> 8968.3878 | L28: =H28*1% -> 2989.4626 | N28: =H28-I28-J28-K28-L28-M28 -> 270695.84
G29: 4852 | H29: 797619.31 | I29: =H29*4.8% -> 38285.727 | J29: =H29*0.65% -> 5184.5255 | K29: =H29*3% -> 23928.579 | L29: =H29*1% -> 7976.1931 | N29: =H29-I29-J29-K29-L29-M29 -> 722244.29
G30: 45 | H30: 522899.09 | I30: =H30*4.8% -> 25099.156 | J30: =H30*0.65% -> 3398.8441 | K30: =H30*3% -> 15686.973 | L30: =H30*1% -> 5228.9909 | N30: =H30-I30-J30-K30-L30-M30 -> 473485.13
G31: 43 | H31: 219339.4 | I31: =H31*4.8% -> 10528.291 | J31: =H31*0.65% -> 1425.7061 | K31: =H31*3% -> 6580.182 | L31: =H31*1% -> 2193.394 | N31: =H31-I31-J31-K31-L31-M31 -> 198611.83
G32: 1139 | H32: 202159.33 | I32: =H32*4.8% -> 9703.6478 | J32: =H32*0.65% -> 1314.0356 | K32: =H32*3% -> 6064.7799 | L32: =H32*1% -> 2021.5933 | N32: =H32-I32-J32-K32-L32-M32 -> 183055.27
A33: SALDO FINAL: | B33: =B3+B4-B19 -> 230063.26 | G33: 202600042 | H33: 306579.11 | I33: =H33*4.8% -> 14715.797 | J33: =H33*0.65% -> 1992.7642 | K33: =H33*3% -> 9197.3733 | L33: =H33*1% -> 3065.7911 | N33: =H33-I33-J33-K33-L33-M33 -> 277607.38
G34: 202600068 | H34: 424776.87 | I34: =H34*4.8% -> 20389.29 | J34: =H34*0.65% -> 2761.0497 | K34: =H34*3% -> 12743.306 | L34: =H34*1% -> 4247.7687 | N34: =H34-I34-J34-K34-L34-M34 -> 384635.46
G35: 3140 | H35: 179139.3 | I35: =H35*4.8% -> 8598.6864 | J35: =H35*0.65% -> 1164.4054 | K35: =H35*3% -> 5374.179 | L35: =H35*1% -> 1791.393 | M35: =H35*5% -> 8956.965 | N35: =H35-I35-J35-K35-L35-M35 -> 153253.67
G36: 3141 | H36: 56000.44 | I36: =H36*4.8% -> 2688.0211 | J36: =H36*0.65% -> 364.00286 | K36: =H36*3% -> 1680.0132 | L36: =H36*1% -> 560.0044 | M36: =H36*5% -> 2800.022 | N36: =H36-I36-J36-K36-L36-M36 -> 47908.376
G37: Total | H37: =SUM(H6:H36) -> 11365183 | I37: =SUM(I6:I36) -> 545528.76 | J37: =SUM(J6:J36) -> 73873.686 | K37: =SUM(K6:K36) -> 340955.47 | L37: =SUM(L6:L36) -> 113651.83 | M37: =SUM(M6:M36) -> 11756.987 | N37: =SUM(N6:N36) -> 10279416

Sheet 13.07.26
A1: CONTA: 200000 AGÊNCIA: 3309
A3: SALDO INICIAL: | B3: ='10.07.26'!B33 -> 230063.26
A4: Recebimentos | B4: =SUM(B5:B18) -> 32822.04 | C4: SITUAÇÃO | D4: NÚMERO DO RECEBIMENTO | E4: TIPO DE SERVIÇO | G4: NOTA FISCAL | H4: VALOR BRUTO NF | I4: ISS | J4: VALOR LIQUIDO
A5: Desbl Judicial-Bacen Jud 573.630.001 | B5: 32822.04 | C5: VALOR LANÇADO | D5: 1307001-GYN | E5: BLOQ/DESBL/ALVARA JUD TRAB | I5: =H5*2% -> 0 | J5: =H5-I5 -> 0
G8: NOTA FISCAL | H8: VALOR BRUTO NF | I8: IR | J8: PIS | K8: COFINS | L8: CSLL | M8: ISS | N8: VALOR LIQUIDO
J9: =H9*0.65% -> 0 | K9: =H9*3% -> 0 | L9: =H9*1% -> 0 | N9: =H9-I9-J9-K9-L9-M9 -> 0
G12: NOTA FISCAL | H12: VALOR BRUTO NF | I12: IR | J12: PIS | K12: COFINS | L12: CSLL | M12: ISS | N12: VALOR LIQUIDO
I13: =H13*1.5% -> 0 | J13: =H13*0.65% -> 0 | K13: =H13*3% -> 0 | L13: =H13*1% -> 0 | M13: =H13*5% -> 0 | N13: =H13-I13-J13-K13-L13-M13 -> 0
A19: Pagamentos | B19: =SUM(B20:B32) -> 62876.3 | C19: SITUAÇÃO | D19: NÚMERO DO RECEBIMENTO | E19: TIPO DE SERVIÇO
A20: Transferência enviada 553.309.000.205.826 13/07 10:39 BB TEC 00042318949000184 | B20: 62876.3 | C20: VALOR LANÇADO | E20: TRANSFERÊNCIA
A33: SALDO FINAL: | B33: =B3+B4-B19 -> 200009

Sheet 14.07.26
A1: CONTA: 200000 AGÊNCIA: 3309
A3: SALDO INICIAL: | B3: ='13.07.26'!B33 -> 200009
A4: Recebimentos | B4: =SUM(B5:B18) -> 9726660.7 | C4: SITUAÇÃO | D4: NÚMERO DO RECEBIMENTO | E4: TIPO DE SERVIÇO
A5: Recebimento Fornecedor 01.378.407/0001-10 ALIANCA DO BRASIL S | B5: 16.34 | C5: VALOR LANÇADO | D5: 1407001-GYN | E5: DEVOLUCAO SEGUROS
A6: Crédito Sistema CDA Pgt.BB Con202285580006/0052 / 1 | B6: 4868680.3 | C6: VALOR LANÇADO | D6: 1407002-GYN | E6: SOLUCAO HIVEPLACE
A7: Crédito Sistema CDA 94.831.083 Pgt.BB Con202185580063/0056 / 1 | B7: 199652.59 | C7: VALOR LANÇADO | D7: 1407003-GYN | E7: E-MAIL MARKETING BB | G7: NOTA FISCAL | H7: VALOR BRUTO NF | I7: IR | J7: PIS | K7: COFINS | L7: CSLL | M7: ISS | N7: VALOR LIQUIDO
A8: Crédito Sistema CDA Pgt.BB Con202485580039/0019 / 1 | B8: 3789144.3 | C8: VALOR LANÇADO | D8: 1407004-GYN | E8: SUP TEC SW LICENTER | J8: =H8*0.65% -> 0 | K8: =H8*3% -> 0 | L8: =H8*1% -> 0 | N8: =H8-I8-J8-K8-L8-M8 -> 0
A9: Crédito Sistema CDA Pgt.BB Con202374214555/0036 / 1 | B9: 83023.75 | C9: VALOR LANÇADO | D9: 1407005-GYN | E9: SUP TEC SW LICENTER
A10: Crédito Sistema CDA Pgt.BB Con202574214470/0011 / 1 | B10: 416861.64 | C10: VALOR LANÇADO | D10: 1407006-GYN | E10: SOLUCAO HIVEPLACE
A11: Crédito Sistema CDA 94.839.488 Pgt.BB Con202474213303/0023 / 1 | B11: 353765.03 | C11: VALOR LANÇADO | D11: 1407007-GYN | E11: SOLUCAO HIVEPLACE | G11: NOTA FISCAL | H11: VALOR BRUTO NF | I11: IR 1,5% | J11: VALOR LIQUIDO
A12: Crédito Sistema CDA Pgt.BB Con202474210685/0029 / 1 | B12: 15516.77 | C12: VALOR LANÇADO | D12: 1407008-GYN | E12: SERV GED BB | I12: =H12*1.5% -> 0 | J12: =H12-I12 -> 0
A13: Bloq Judicial-Bacen Jud 12.647.273.220.301 | B13: 21.075,51 *
G14: NOTA FISCAL | H14: VALOR BRUTO NF | I14: IR | J14: PIS | K14: COFINS | L14: CSLL | M14: ISS | N14: VALOR LIQUIDO
N15: =H15-I15-J15-K15-L15-M15 -> 0
N16: =H16-I16-J16-K16-L16-M16 -> 0
G17: TOTAL | H17: =SUM(H15:H16) -> 0 | I17: =SUM(I15:I16) -> 0 | J17: =SUM(J15:J16) -> 0 | K17: =SUM(K15:K16) -> 0 | L17: =SUM(L15:L16) -> 0 | M17: =SUM(M15:M16) -> 0 | N17: =SUM(N15:N16) -> 0
A19: Pagamentos | B19: =SUM(B20:B33) -> 4221522.7 | C19: SITUAÇÃO | D19: NÚMERO DO RECEBIMENTO | E19: TIPO DE SERVIÇO
A20: Transferência enviada 553.309.000.205.826 14/07 09:29 BB TEC 00042318949000184 | B20: 4200447.2 | C20: VALOR LANÇADO | E20: TRANSFERÊNCIA
A21: Bloq Judicial-Bacen Jud 12.647.273.220.301 | B21: 21075.51 | C21: VALOR LANÇADO | D21: 14-JUL-26001001200000/10 | E21: BLOQ/DESBL/ALVARA JUD TRAB
A34: SALDO FINAL: | B34: =B3+B4-B19 -> 5705147

Sheet 15.07.26
A1: CONTA: 200000 AGÊNCIA: 3309
A3: SALDO INICIAL: | B3: ='14.07.26'!B34 -> 5705147
A4: Recebimentos | B4: =SUM(B5:B18) -> 7144095.9 | C4: SITUAÇÃO | D4: NÚMERO DO RECEBIMENTO | E4: TIPO DE SERVIÇO | G4: NOTA FISCAL | H4: VALOR BRUTO NF | I4: IR | J4: VALOR LIQUIDO
A5: Transferência recebida 553.307.000.036.846 15/07 17:11 BB CONSORCIOS ADMINISTRA | B5: 3282740.6 | C5: VALOR LANÇADO | D5: 1507001-GYN | E5: COBAN CONSORCIOS | G5: 100 | H5: 3332731.6 | I5: =1.5%*H5 -> 49990.974 | J5: =H5-I5 -> 3282740.6
A6: Crédito Sistema CDA Pgt.BB Con202585580001/0017 / 1 | B6: 3845681.9 | C6: VALOR LANÇADO | D6: 1507002-GYN | E6: MANUT REDE MAN BB
A7: Crédito Sistema CDA 94.842.682 Pgt.BB Con202274213769/0051 / 1 | B7: 15673.35 | C7: VALOR LANÇADO | D7: 1507003-GYN | E7: SUP TEC SW LICENTER | G7: NOTA FISCAL | H7: VALOR BRUTO NF | I7: IR | J7: PIS | K7: COFINS | L7: CSLL | M7: ISS | N7: VALOR LIQUIDO
G8: 3126 | H8: 2746397.6 | I8: =H8*4.8% -> 131827.09 | J8: =H8*0.65% -> 17851.585 | K8: =H8*3% -> 82391.929 | L8: =H8*1% -> 27463.977 | M8: =H8*2% -> 54927.953 | N8: =H8-I8-J8-K8-L8-M8 -> 2431935.1
G9: 3128 | H9: 774824.46 | I9: =H9*4.8% -> 37191.574 | J9: =H9*0.65% -> 5036.359 | K9: =H9*3% -> 23244.734 | L9: =H9*1% -> 7748.2446 | M9: =H9*2% -> 15496.489 | N9: =H9-I9-J9-K9-L9-M9 -> 686107.06
G10: 58 | H10: 109707.12 | I10: =H10*4.8% -> 5265.9418 | J10: =H10*0.65% -> 713.09628 | K10: =H10*3% -> 3291.2136 | L10: =H10*1% -> 1097.0712 | N10: =H10-I10-J10-K10-L10-M10 -> 99339.797
G11: 57 | H11: 72179.04 | I11: =H11*4.8% -> 3464.5939 | J11: =H11*0.65% -> 469.16376 | K11: =H11*3% -> 2165.3712 | L11: =H11*1% -> 721.7904 | N11: =H11-I11-J11-K11-L11-M11 -> 65358.121
G12: 58 | H12: 28681.6 | I12: =H12*4.8% -> 1376.7168 | J12: =H12*0.65% -> 186.4304 | K12: =H12*3% -> 860.448 | L12: =H12*1% -> 286.816 | N12: =H12-I12-J12-K12-L12-M12 -> 25971.189
G13: 4846 | H13: 133692.11 | I13: =H13*4.8% -> 6417.2213 | J13: =H13*0.65% -> 868.99871 | K13: =H13*3% -> 4010.7633 | L13: =H13*1% -> 1336.9211 | N13: =H13-I13-J13-K13-L13-M13 -> 121058.21
G14: 4847 | H14: 109707.12 | I14: =H14*4.8% -> 5265.9418 | J14: =H14*0.65% -> 713.09628 | K14: =H14*3% -> 3291.2136 | L14: =H14*1% -> 1097.0712 | N14: =H14-I14-J14-K14-L14-M14 -> 99339.797
G15: 3127 | H15: 357507.19 | I15: =H15*4.8% -> 17160.345 | J15: =H15*0.65% -> 2323.7967 | K15: =H15*3% -> 10725.216 | L15: =H15*1% -> 3575.0719 | M15: =H15*2% -> 7150.1438 | N15: =H15-I15-J15-K15-L15-M15 -> 316572.62
G16: TOTAL | H16: =SUM(H8:H15) -> 4332696.3 | I16: =SUM(I8:I15) -> 207969.42 | J16: =SUM(J8:J15) -> 28162.526 | K16: =SUM(K8:K15) -> 129980.89 | L16: =SUM(L8:L15) -> 43326.963 | M16: =SUM(M8:M15) -> 77574.586 | N16: =SUM(N8:N15) -> 3845681.9
A19: Pagamentos | B19: =SUM(B20:B29) -> 5520811.4 | C19: SITUAÇÃO | D19: NÚMERO DO RECEBIMENTO | E19: TIPO DE SERVIÇO
A20: Transferência enviada 553.309.000.205.826 15/07 14:32 BB TEC 00042318949000184 | B20: 5520811.4 | C20: VALOR LANÇADO | E20: TRANSFERÊNCIA
A30: SALDO FINAL: | B30: =B3+B4-B19 -> 7328431.5

Sheet 16.06.26
A1: CONTA: 200000 AGÊNCIA: 3309
A3: SALDO INICIAL: | B3: ='15.07.26'!B30 -> 7328431.5
A4: Recebimentos | B4: =SUM(B5:B18) -> 0 | C4: SITUAÇÃO | D4: NÚMERO DO RECEBIMENTO | E4: TIPO DE SERVIÇO | G4: NOTA FISCAL | H4: VALOR BRUTO NF | I4: IR 1,5% | J4: VALOR LIQUIDO
I5: =H5*1.5% -> 0 | J5: =H5-I5 -> 0
G7: NOTA FISCAL | H7: VALOR BRUTO NF | I7: IR 4,8% | J7: VALOR LIQUIDO
I8: =H8*4.8% -> 0 | J8: =H8-I8 -> 0
A19: Pagamentos | B19: =SUM(B20:B32) -> 7128422.5 | C19: SITUAÇÃO | D19: NÚMERO DO RECEBIMENTO | E19: TIPO DE SERVIÇO
A20: Transferência enviada 553.309.000.205.826 16/07 10:44 BB TEC 00042318949000184 | B20: 7128422.5 | C20: VALOR LANÇADO | E20: TRANSFERÊNCIA
A33: SALDO FINAL: | B33: =B3+B4-B19 -> 200009

Sheet 17.07.26
A1: CONTA: 200000 AGÊNCIA: 3309
A3: SALDO INICIAL: | B3: ='16.06.26'!B33 -> 200009
A4: Recebimentos | B4: =SUM(B5:B18) -> 161393.93 | C4: SITUAÇÃO | D4: NÚMERO DO RECEBIMENTO | E4: TIPO DE SERVIÇO
A5: TED-Pag Fornecedores 100.427.047 745 0001 07275920000161 LENOVO TECNOLO | B5: 18019 | C5: VALOR LANÇADO | D5: 1707001-GYN | E5: SERV INST PERIF | F5: 3020 e 3021 | G5: NOTA FISCAL | H5: VALOR BRUTO NF | I5: IR 1,5% | J5: VALOR LIQUIDO
A6: Recebimentos Diversos 14.967.001.100.547 13.937.073/0001-56 BAHIA SECRETARIA DA | B6: 125343.27 | C6: VALOR LANÇADO | D6: 1707002-GYN | E6: SOLUCAO HIVEPLACE | I6: =H6*1.5% -> 0 | J6: =H6-I6 -> 0
A7: Recebimentos Diversos 14.967.001.100.549 13.937.073/0001-56 BAHIA SECRETARIA DA | B7: 17888.63 | C7: VALOR LANÇADO
A8: Devolução ISSQN Retido 24.370.766.010.100 | B8: 90.68 | C8: VALOR LANÇADO | D8: 1707003-GYN | E8: DEVOLUCAO DE ISS CLIENTES | G8: NOTA FISCAL | H8: VALOR BRUTO NF | I8: IR 1,5% | J8: VALOR LIQUIDO
A9: Devolução ISSQN Retido 24.370.767.010.100 | B9: 52.35 | C9: VALOR LANÇADO | D9: 1707004-GYN | E9: DEVOLUCAO DE ISS CLIENTES | G9: 3177 | H9: 150453.68 | I9: =H9*1.5% -> 2256.8052 | J9: =H9-I9 -> 148196.87
G11: NOTA FISCAL | H11: VALOR BRUTO NF | I11: IR | J11: PIS | K11: COFINS | L11: CSLL | M11: ISS | N11: VALOR LIQUIDO
G12: 3177 | H12: 150453.68 | I12: =H12*4.8% -> 7221.7766 | N12: =H12-I12-J12-K12-L12-M12 -> 143231.9
J14: 143231.9
G15: 15972
G16: 2047
A19: Pagamentos | B19: =SUM(B20:B32) -> 143231.9 | C19: SITUAÇÃO | D19: NÚMERO DO RECEBIMENTO | E19: TIPO DE SERVIÇO
A20: Transferência enviada 553.309.000.205.826 17/07 10:10 BB TEC 00042318949000184 | B20: 143231.9 | C20: VALOR LANÇADO | E20: TRANSFERÊNCIA
A33: SALDO FINAL: | B33: =B3+B4-B19 -> 218171.03

Sheet 20.07.26
A1: CONTA: 200000 AGÊNCIA: 3309
A3: SALDO INICIAL: | B3: ='17.07.26'!B33 -> 218171.03
A4: Recebimentos | B4: =SUM(B5:B14) -> 31239.75 | C4: SITUAÇÃO | D4: NÚMERO DO RECEBIMENTO | E4: TIPO DE SERVIÇO | G4: NOTA FISCAL | H4: VALOR BRUTO NF | I4: IR | J4: PIS | K4: COFINS | L4: CSLL | M4: ISS | N4: VALOR LIQUIDO
A5: Crédito Sistema CDA 95.123.448 PAGTO.BB DEMAIS DESP.OPER./CORRESPONDE | B5: 31239.75 | C5: VALOR LANÇADO | D5: 2007001-GYN | E5: CORRESPOND BANCARIO | G5: 116 | H5: 34500 | I5: =H5*4.8% -> 1656 | J5: =H5*0.65% -> 224.25 | K5: =H5*3% -> 1035 | L5: =H5*1% -> 345 | N5: =H5-I5-J5-K5-L5-M5 -> 31239.75
G7: NOTA FISCAL | H7: VALOR BRUTO NF | I7: IR | J7: PIS | K7: COFINS | L7: CSLL | M7: ISS | N7: VALOR LIQUIDO
I8: =H8*4.8% -> 0 | J8: =H8*0.65% -> 0 | K8: =H8*3% -> 0 | L8: =H8*1% -> 0 | N8: =H8-I8-J8-K8-L8-M8 -> 0
G14: NOTA FISCAL | H14: VALOR BRUTO NF | I14: IR | J14: PIS | K14: COFINS | L14: CSLL | M14: ISS | N14: VALOR LIQUIDO
A15: Pagamentos | B15: =SUM(B16:B28) -> 18935.49 | C15: SITUAÇÃO | D15: NÚMERO DO RECEBIMENTO | E15: TIPO DE SERVIÇO | I15: =H15*4.8% -> 0 | J15: =H15*0.65% -> 0 | K15: =H15*3% -> 0 | L15: =H15*1% -> 0 | N15: =H15-I15-J15-K15-L15-M15 -> 0
A16: Transferência enviada 553.309.000.205.826 20/07 14:52 BB TEC 00042318949000184 | B16: 18162.03 | C16: VALOR LANÇADO | E16: TRANSFERÊNCIA | I16: =H16*4.8% -> 0 | J16: =H16*0.65% -> 0 | K16: =H16*3% -> 0 | L16: =H16*1% -> 0 | N16: =H16-I16-J16-K16-L16-M16 -> 0
A17: Débito Autorizado 2.014.695.001.002 | B17: 773.46 | C17: VALOR LANÇADO | D17: 20-JUL-26001001200000/3 | E17: CUSTO DE LICITACOES | I17: =H17*4.8% -> 0 | J17: =H17*0.65% -> 0 | K17: =H17*3% -> 0 | L17: =H17*1% -> 0 | N17: =H17-I17-J17-K17-L17-M17 -> 0
I18: =H18*4.8% -> 0 | J18: =H18*0.65% -> 0 | K18: =H18*3% -> 0 | L18: =H18*1% -> 0 | N18: =H18-I18-J18-K18-L18-M18 -> 0
I19: =H19*4.8% -> 0 | J19: =H19*0.65% -> 0 | K19: =H19*3% -> 0 | L19: =H19*1% -> 0 | N19: =H19-I19-J19-K19-L19-M19 -> 0
I20: =H20*4.8% -> 0 | J20: =H20*0.65% -> 0 | K20: =H20*3% -> 0 | L20: =H20*1% -> 0 | N20: =H20-I20-J20-K20-L20-M20 -> 0
I21: =H21*4.8% -> 0 | J21: =H21*0.65% -> 0 | K21: =H21*3% -> 0 | L21: =H21*1% -> 0 | N21: =H21-I21-J21-K21-L21-M21 -> 0
G22: TOTAL | H22: =SUM(H15:H21) -> 0 | I22: =SUM(I15:I21) -> 0 | J22: =SUM(J15:J21) -> 0 | K22: =SUM(K15:K21) -> 0 | L22: =SUM(L15:L21) -> 0 | M22: =SUM(M15:M21) -> 0 | N22: =SUM(N15:N21) -> 0
A29: SALDO FINAL: | B29: =B3+B4-B15 -> 230475.29

Sheet 21.07.26
A1: CONTA: 200000 AGÊNCIA: 3309
A3: SALDO INICIAL: | B3: ='20.07.26'!B29 -> 230475.29 | C3: 1469.14 | D3: =B5/C3-1 -> -0.04649659
A4: Recebimentos | B4: =SUM(B5:B18) -> 1400.83 | C4: SITUAÇÃO | D4: NÚMERO DO RECEBIMENTO | E4: TIPO DE SERVIÇO | G4: NOTA FISCAL | H4: VALOR BRUTO NF | I4: IR | J4: PIS | K4: COFINS | L4: CSLL | M4: ISS | N4: VALOR LIQUIDO
A5: Transferência recebida: 21/07 17:33 BB GESTAO REC DTVM AS | B5: 1400.83 | C5: VALOR LANÇADO | D5: 2107001-GYN | E5: SERV IMPRE BBDTVM | G5: 3151 | H5: 1469.14 | J5: =H5*0.65% -> 9.54941 | K5: =H5*3% -> 44.0742 | L5: =H5*1% -> 14.6914 | N5: =H5-I5-J5-K5-L5-M5 -> 1400.825
A19: Pagamentos | B19: =SUM(B20:B32) -> 30466.29 | C19: SITUAÇÃO | D19: NÚMERO DO RECEBIMENTO | E19: TIPO DE SERVIÇO
A20: Transferência enviada: 553.309.000.205.826 21/07 16:22 BB TEC 00042318949000184 | B20: 30466.29 | C20: VALOR LANÇADO | E20: TRANSFERÊNCIA
A33: SALDO FINAL: | B33: =B3+B4-B19 -> 201409.83

Sheet 22.07.26
A1: CONTA: 200000 AGÊNCIA: 3309
A3: SALDO INICIAL: | B3: ='21.07.26'!B33 -> 201409.83
A4: Recebimentos | B4: =SUM(B5:B17) -> 11458156 | C4: SITUAÇÃO | D4: NÚMERO DO RECEBIMENTO | E4: TIPO DE SERVIÇO
A5: Crédito CASSI: 33.719.485/0001-27 CAIXA DE ASSISTENCI | B5: 70005.1 | C5: VALOR LANÇADO | D5: 2207001-GYN | E5: SUP TEC SOFTWARE | G5: NOTA FISCAL | H5: VALOR BRUTO NF | I5: ISS | J5: VALOR LIQUIDO
A6: Crédito Sistema CDA: Pgt.BB Con202585580006/0016 / 1 | B6: 10800057 | C6: VALOR LANÇADO | D6: 2207002-GYN | E6: SOLUCAO HIVEPLACE | G6: 3152 | H6: 71433.78 | I6: =H6*2% -> 1428.6756 | J6: =H6-I6 -> 70005.104
A7: Crédito Sistema CDA: Pgt.BB Con202385580035/0030 / 1 | B7: 588094.21 | C7: VALOR LANÇADO | D7: 2207003-GYN | E7: SUP SOFTW TRIBUNAIS
G10: NOTA FISCAL | H10: VALOR BRUTO NF | I10: IR | J10: VALOR LIQUIDO
I11: =H11*4.8% -> 0 | J11: =H11-I11 -> 0
A18: Pagamentos | B18: =SUM(B19:B33) -> 11459559 | C18: SITUAÇÃO | D18: NÚMERO DO RECEBIMENTO | E18: TIPO DE SERVIÇO
A19: Transferência enviada 553.309.000.205.826 22/07 12:30 BB TEC 00042318949000184 | B19: 11459557 | C19: VALOR LANÇADO | E19: TRANSFERÊNCIA
A20: Tarifa Transf Recurso-E/I: Cobrança referente 22/07/2026 | B20: 1.7 | C20: VALOR LANÇADO | D20: 22-JUL-26001001200000/5 | E20: TARIFAS
A34: SALDO FINAL: | B34: =B3+B4-B18 -> 200007.3

Sheet 23.07.26
A1: CONTA: 200000 AGÊNCIA: 3309
A3: SALDO INICIAL: | B3: ='22.07.26'!B34 -> 200007.3
A4: Recebimentos | B4: =SUM(B5:B15) -> 2018827.4 | C4: SITUAÇÃO | D4: NÚMERO DO RECEBIMENTO | E4: TIPO DE SERVIÇO
A5: Transferência recebida: 23/07 18:26 BB CONSORCIOS ADMINISTRA | B5: 1996834.5 | C5: VALOR LANÇADO | D5: 2307001-GYN | E5: COBAN CONSORCIOS | G5: NOTA FISCAL | H5: VALOR BRUTO NF | I5: IR 1,5% | J5: VALOR LIQUIDO
A6: Transferência recebida: 553.309.000.205.826 23/07 12:54 BB TECNOLOGIA E SERVICOS | B6: 21992.96 | C6: VALOR LANÇADO | E6: TRANSFERÊNCIA | G6: 117 | H6: 2027243.1 | I6: =H6*1.5% -> 30408.647 | J6: =H6-I6 -> 1996834.5
A7: Bloq Judicial-Bacen Jud 12.658.349.970.901 | B7: 21.991,26 * | C7: VALOR BLOQUEADO NÃO AFETA O SALDO, NÃO LANÇAR
A16: Pagamentos | B16: =SUM(B17:B29) -> 21991.26 | C16: SITUAÇÃO | D16: NÚMERO DO RECEBIMENTO | E16: TIPO DE SERVIÇO
A17: Bloq Judicial-Bacen Jud 12.658.349.970.901 | B17: 21991.26 | C17: VALOR LANÇADO | D17: 23-JUL-26001001200000/3 | E17: BLOQ/DESBL/ALVARA JUD TRAB
A30: SALDO FINAL: | B30: =B3+B4-B16 -> 2196843.5

Sheet 24.07.26
A1: CONTA: 200000 AGÊNCIA: 3309
C2: 9247.7 | D2: =B5/C2-1 -> -0.019999567 | G2: NOTA FISCAL | H2: VALOR BRUTO NF | I2: ISS | J2: VALOR LIQUIDO
A3: SALDO INICIAL: | B3: ='23.07.26'!B30 -> 2196843.5 | G3: 3191 | H3: 9247.7 | I3: =H3*2% -> 184.954 | J3: =H3-I3 -> 9062.746
A4: Recebimentos | B4: =SUM(B5:B28) -> 3990343.6 | C4: SITUAÇÃO | D4: NÚMERO DO RECEBIMENTO | E4: TIPO DE SERVIÇO
A5: Crédito CASSI: 33.719.485/0001-27 CAIXA DE ASSISTENCI | B5: 9062.75 | C5: VALOR LANÇADO | D5: 2407001-GYN | E5: GERENC MENSAGENS SMS
A6: ORPAG ORIGEM EXTERIOR | B6: 87526.93 | C6: VALOR LANÇADO | D6: 2407002-GYN | E6: FAB DESENV SOFT BB
A7: Crédito Sistema CDA: Pgt.BB Con202374212408/0039 / 1 | B7: 131535.21 | C7: VALOR LANÇADO | D7: 2407003-GYN | E7: SOLUCAO HCL
A8: Crédito Sistema CDA: Pgt.BB Con202585580036/0009 / 1 | B8: 661934.04 | C8: VALOR LANÇADO | D8: 2407004-GYN | E8: SERV NOBREAK BB
A9: Crédito Sistema CDA: Pgt.BB Con202285580044/0042 / 1 | B9: 2583053.7 | C9: VALOR LANÇADO | D9: 2407005-GYN | E9: APLICAT BANCO BRASIL
A10: Crédito Sistema CDA: Pgt.BB Con202585580037/0009 / 1 | B10: 517230.93 | C10: VALOR LANÇADO | D10: 2407006-GYN | E10: SERV NOBREAK BB | G10: NOTA FISCAL | H10: VALOR BRUTO NF | I10: IR | J10: PIS | K10: COFINS | L10: CSLL | M10: ISS | N10: VALOR LIQUIDO
I11: =H11*4.8% -> 0 | J11: =H11*0.65% -> 0 | K11: =H11*3% -> 0 | L11: =H11*1% -> 0 | M11: =H11*5% -> 0 | N11: =H11-I11-J11-K11-L11-M11 -> 0
I12: =H12*4.8% -> 0 | J12: =H12*0.65% -> 0 | K12: =H12*3% -> 0 | L12: =H12*1% -> 0 | N12: =H12-I12-J12-K12-L12-M12 -> 0
G13: TOTAL | H13: =SUM(H11:H12) -> 0 | I13: =SUM(I11:I12) -> 0 | J13: =SUM(J11:J12) -> 0 | K13: =SUM(K11:K12) -> 0 | L13: =SUM(L11:L12) -> 0 | M13: =SUM(M11:M12) -> 0 | N13: =SUM(N11:N12) -> 0
G15: NOTA FISCAL | H15: VALOR BRUTO NF | I15: IR | J15: PIS | K15: COFINS | L15: CSLL | M15: ISS | N15: VALOR LIQUIDO
I16: =H16*4.8% -> 0 | J16: =H16*0.65% -> 0 | K16: =H16*3% -> 0 | L16: =H16*1% -> 0 | M16: =H16*5% -> 0 | N16: =H16-I16-J16-K16-L16-M16 -> 0
I17: =H17*4.8% -> 0 | J17: =H17*0.65% -> 0 | K17: =H17*3% -> 0 | L17: =H17*1% -> 0 | N17: =H17-I17-J17-K17-L17-M17 -> 0
G18: TOTAL | H18: =SUM(H16:H17) -> 0 | I18: =SUM(I16:I17) -> 0 | J18: =SUM(J16:J17) -> 0 | K18: =SUM(K16:K17) -> 0 | L18: =SUM(L16:L17) -> 0 | M18: =SUM(M16:M17) -> 0 | N18: =SUM(N16:N17) -> 0
G20: NOTA FISCAL | H20: VALOR BRUTO NF | I20: IR | J20: PIS | K20: COFINS | L20: CSLL | M20: ISS | N20: VALOR LIQUIDO
I21: =H21*4.8% -> 0 | J21: =H21*0.65% -> 0 | K21: =H21*3% -> 0 | L21: =H21*1% -> 0 | M21: =H21*5% -> 0 | N21: =H21-I21-J21-K21-L21-M21 -> 0
I22: =H22*4.8% -> 0 | J22: =H22*0.65% -> 0 | K22: =H22*3% -> 0 | L22: =H22*1% -> 0 | M22: =H22*5% -> 0 | N22: =H22-I22-J22-K22-L22-M22 -> 0
G23: TOTAL | H23: =SUM(H21:H22) -> 0 | I23: =SUM(I21:I22) -> 0 | J23: =SUM(J21:J22) -> 0 | K23: =SUM(K21:K22) -> 0 | L23: =SUM(L21:L22) -> 0 | M23: =SUM(M21:M22) -> 0 | N23: =SUM(N21:N22) -> 0
G25: NOTA FISCAL | H25: VALOR BRUTO NF | I25: IR | J25: PIS | K25: COFINS | L25: CSLL | M25: ISS | N25: VALOR LIQUIDO
I26: =H26*4.8% -> 0 | J26: =H26*0.65% -> 0 | K26: =H26*3% -> 0 | L26: =H26*1% -> 0 | M26: =H26*5% -> 0 | N26: =H26-I26-J26-K26-L26-M26 -> 0
I27: =H27*4.8% -> 0 | J27: =H27*0.65% -> 0 | K27: =H27*3% -> 0 | L27: =H27*1% -> 0 | M27: =H27*5% -> 0 | N27: =H27-I27-J27-K27-L27-M27 -> 0
G28: TOTAL | H28: =SUM(H26:H27) -> 0 | I28: =SUM(I26:I27) -> 0 | J28: =SUM(J26:J27) -> 0 | K28: =SUM(K26:K27) -> 0 | L28: =SUM(L26:L27) -> 0 | M28: =SUM(M26:M27) -> 0 | N28: =SUM(N26:N27) -> 0
A29: Pagamentos | B29: =SUM(B30:B42) -> 5890590.1 | C29: SITUAÇÃO | D29: NÚMERO DO RECEBIMENTO | E29: TIPO DE SERVIÇO
A30: Transferência enviada: 553.309.000.205.826 24/07 10:23 BB TEC 00042318949000184 | B30: 5890588.4 | C30: VALOR LANÇADO | E30: TRANSFERÊNCIA | G30: NOTA FISCAL | H30: VALOR BRUTO NF | I30: IR | J30: PIS | K30: COFINS | L30: CSLL | M30: ISS | N30: VALOR LIQUIDO
A31: Tarifa Transf Recurso-E/I: Cobrança referente 24/07/2026 | B31: 1.7 | C31: VALOR LANÇADO | D31: 24-JUL-26001001200000/8 | E31: TARIFAS | I31: =H31*4.8% -> 0 | J31: =H31*0.65% -> 0 | K31: =H31*3% -> 0 | L31: =H31*1% -> 0 | N31: =H31-I31-J31-K31-L31-M31 -> 0
G33: NOTA FISCAL | H33: VALOR BRUTO NF | I33: IR | J33: PIS | K33: COFINS | L33: CSLL | M33: ISS | N33: VALOR LIQUIDO
I34: =H34*4.8% -> 0 | J34: =H34*0.65% -> 0 | K34: =H34*3% -> 0 | L34: =H34*1% -> 0 | M34: =H34*5% -> 0 | N34: =H34-I34-J34-K34-L34-M34 -> 0
I35: =H35*4.8% -> 0 | J35: =H35*0.65% -> 0 | K35: =H35*3% -> 0 | L35: =H35*1% -> 0 | N35: =H35-I35-J35-K35-L35-M35 -> 0
G36: TOTAL | H36: =SUM(H34:H35) -> 0 | I36: =SUM(I34:I35) -> 0 | J36: =SUM(J34:J35) -> 0 | K36: =SUM(K34:K35) -> 0 | L36: =SUM(L34:L35) -> 0 | M36: =SUM(M34:M35) -> 0 | N36: =SUM(N34:N35) -> 0
G38: NOTA FISCAL | H38: VALOR BRUTO NF | I38: IR | J38: PIS | K38: COFINS | L38: CSLL | M38: ISS | N38: VALOR LIQUIDO
I39: =H39*4.8% -> 0 | J39: =H39*0.65% -> 0 | K39: =H39*3% -> 0 | L39: =H39*1% -> 0 | M39: =H39*5% -> 0 | N39: =H39-I39-J39-K39-L39-M39 -> 0
I40: =H40*4.8% -> 0 | J40: =H40*0.65% -> 0 | K40: =H40*3% -> 0 | L40: =H40*1% -> 0 | M40: =H40*5% -> 0 | N40: =H40-I40-J40-K40-L40-M40 -> 0
G41: TOTAL | H41: =SUM(H39:H40) -> 0 | I41: =SUM(I39:I40) -> 0 | J41: =SUM(J39:J40) -> 0 | K41: =SUM(K39:K40) -> 0 | L41: =SUM(L39:L40) -> 0 | M41: =SUM(M39:M40) -> 0 | N41: =SUM(N39:N40) -> 0
A43: SALDO FINAL: | B43: =B3+B4-B29 -> 296596.98

Sheet 27.07.26
A1: CONTA: 200000 AGÊNCIA: 3309
A3: SALDO INICIAL: | B3: ='24.07.26'!B43 -> 296596.98
A4: Recebimentos | B4: =SUM(B5:B18) -> 0 | C4: SITUAÇÃO | D4: NÚMERO DO RECEBIMENTO | E4: TIPO DE SERVIÇO | G4: NOTA FISCAL | H4: VALOR BRUTO NF | I4: IR | J4: PIS | K4: COFINS | L4: CSLL | M4: ISS | N4: VALOR LIQUIDO
I5: =H5*4.8% -> 0 | J5: =H5*0.65% -> 0 | K5: =H5*3% -> 0 | L5: =H5*1% -> 0 | N5: =H5-I5-J5-K5-L5-M5 -> 0
I6: =H6*4.8% -> 0 | J6: =H6*0.65% -> 0 | K6: =H6*3% -> 0 | L6: =H6*1% -> 0 | N6: =H6-I6-J6-K6-L6-M6 -> 0
G7: TOTAL | H7: =SUM(H5:H6) -> 0 | I7: =SUM(I5:I6) -> 0 | J7: =SUM(J5:J6) -> 0 | K7: =SUM(K5:K6) -> 0 | L7: =SUM(L5:L6) -> 0 | M7: =SUM(M5:M6) -> 0 | N7: =SUM(N5:N6) -> 0
G10: NOTA FISCAL | H10: VALOR BRUTO NF | I10: IR | J10: PIS | K10: COFINS | L10: CSLL | M10: ISS | N10: VALOR LIQUIDO
I11: =H11*4.8% -> 0 | J11: =H11*0.65% -> 0 | K11: =H11*3% -> 0 | L11: =H11*1% -> 0 | N11: =H11-I11-J11-K11-L11-M11 -> 0
G12: TOTAL | H12: =SUM(H10:H11) -> 0 | I12: =SUM(I10:I11) -> 0 | J12: =SUM(J10:J11) -> 0 | K12: =SUM(K10:K11) -> 0 | L12: =SUM(L10:L11) -> 0 | M12: =SUM(M10:M11) -> 0 | N12: =SUM(N10:N11) -> 0
G14: NOTA FISCAL | H14: VALOR BRUTO NF | I14: IR | J14: PIS | K14: COFINS | L14: CSLL | M14: ISS | N14: VALOR LIQUIDO
I15: =H15*4.8% -> 0 | J15: =H15*0.65% -> 0 | K15: =H15*3% -> 0 | L15: =H15*1% -> 0 | N15: =H15-I15-J15-K15-L15-M15 -> 0
I16: =H16*4.8% -> 0 | J16: =H16*0.65% -> 0 | K16: =H16*3% -> 0 | L16: =H16*1% -> 0 | N16: =H16-I16-J16-K16-L16-M16 -> 0
G17: TOTAL | H17: =SUM(H15:H16) -> 0 | I17: =SUM(I15:I16) -> 0 | J17: =SUM(J15:J16) -> 0 | K17: =SUM(K15:K16) -> 0 | L17: =SUM(L15:L16) -> 0 | M17: =SUM(M15:M16) -> 0 | N17: =SUM(N15:N16) -> 0
A19: Pagamentos | B19: =SUM(B20:B32) -> 96589.68 | C19: SITUAÇÃO | D19: NÚMERO DO RECEBIMENTO | E19: TIPO DE SERVIÇO | G19: NOTA FISCAL | H19: VALOR BRUTO NF | I19: IR | J19: PIS | K19: COFINS | L19: CSLL | M19: ISS | N19: VALOR LIQUIDO
A20: Transferência enviada 553.309.000.205.826 27/07 11:59 BB TEC 00042318949000184 | B20: 96587.98 | C20: VALOR LANÇADO | E20: TRANSFERÊNCIA | I20: =H20*4.8% -> 0 | J20: =H20*0.65% -> 0 | K20: =H20*3% -> 0 | L20: =H20*1% -> 0 | N20: =H20-I20-J20-K20-L20-M20 -> 0
A21: Tarifa Transf Recurso-E/I: Cobrança referente 27/07/2026 | B21: 1.7 | C21: VALOR LANÇADO | D21: 27-JUL-26001001200000/2 | E21: TARIFAS | I21: =H21*4.8% -> 0 | J21: =H21*0.65% -> 0 | K21: =H21*3% -> 0 | L21: =H21*1% -> 0 | N21: =H21-I21-J21-K21-L21-M21 -> 0
G22: TOTAL | H22: =SUM(H20:H21) -> 0 | I22: =SUM(I20:I21) -> 0 | J22: =SUM(J20:J21) -> 0 | K22: =SUM(K20:K21) -> 0 | L22: =SUM(L20:L21) -> 0 | M22: =SUM(M20:M21) -> 0 | N22: =SUM(N20:N21) -> 0
G24: NOTA FISCAL | H24: VALOR BRUTO NF | I24: IR | J24: PIS | K24: COFINS | L24: CSLL | M24: ISS | N24: VALOR LIQUIDO
I25: =H25*4.8% -> 0 | J25: =H25*0.65% -> 0 | K25: =H25*3% -> 0 | L25: =H25*1% -> 0 | N25: =H25-I25-J25-K25-L25-M25 -> 0
G26: TOTAL | H26: =SUM(H24:H25) -> 0 | I26: =SUM(I24:I25) -> 0 | J26: =SUM(J24:J25) -> 0 | K26: =SUM(K24:K25) -> 0 | L26: =SUM(L24:L25) -> 0 | M26: =SUM(M24:M25) -> 0 | N26: =SUM(N24:N25) -> 0
G28: NOTA FISCAL | H28: VALOR BRUTO NF | I28: IR | J28: PIS | K28: COFINS | L28: CSLL | M28: ISS | N28: VALOR LIQUIDO
I29: =H29*4.8% -> 0 | J29: =H29*0.65% -> 0 | K29: =H29*3% -> 0 | L29: =H29*1% -> 0 | N29: =H29-I29-J29-K29-L29-M29 -> 0 | O29: =H29*5% -> 0
I30: =H30*4.8% -> 0 | J30: =H30*0.65% -> 0 | K30: =H30*3% -> 0 | L30: =H30*1% -> 0 | N30: =H30-I30-J30-K30-L30-M30 -> 0
G31: TOTAL | H31: =SUM(H29:H30) -> 0 | I31: =SUM(I29:I30) -> 0 | J31: =SUM(J29:J30) -> 0 | K31: =SUM(K29:K30) -> 0 | L31: =SUM(L29:L30) -> 0 | M31: =SUM(M29:M30) -> 0 | N31: =SUM(N29:N30) -> 0
A33: SALDO FINAL: | B33: =B3+B4-B19 -> 200007.3 | G33: NOTA FISCAL | H33: VALOR BRUTO NF | I33: IR | J33: PIS | K33: COFINS | L33: CSLL | M33: ISS | N33: VALOR LIQUIDO
N34: =H34-I34-J34-K34-L34-M34 -> 0
G35: TOTAL | H35: =SUM(H33:H34) -> 0 | I35: =SUM(I33:I34) -> 0 | J35: =SUM(J33:J34) -> 0 | K35: =SUM(K33:K34) -> 0 | L35: =SUM(L33:L34) -> 0 | M35: =SUM(M33:M34) -> 0 | N35: =SUM(N33:N34) -> 0
G37: NOTA FISCAL | H37: VALOR BRUTO NF | I37: IR | J37: PIS | K37: COFINS | L37: CSLL | M37: ISS | N37: VALOR LIQUIDO
N38: =H38-I38-J38-K38-L38-M38 -> 0
G39: TOTAL | H39: =SUM(H37:H38) -> 0 | I39: =SUM(I37:I38) -> 0 | J39: =SUM(J37:J38) -> 0 | K39: =SUM(K37:K38) -> 0 | L39: =SUM(L37:L38) -> 0 | M39: =SUM(M37:M38) -> 0 | N39: =SUM(N37:N38) -> 0
G41: NOTA FISCAL | H41: VALOR BRUTO NF | I41: IR | J41: PIS | K41: COFINS | L41: CSLL | M41: ISS | N41: VALOR LIQUIDO
I42: =H42*4.8% -> 0 | J42: =H42*0.65% -> 0 | K42: =H42*3% -> 0 | L42: =H42*1% -> 0 | N42: =H42-I42-J42-K42-L42-M42 -> 0
G43: TOTAL | H43: =SUM(H41:H42) -> 0 | I43: =SUM(I41:I42) -> 0 | J43: =SUM(J41:J42) -> 0 | K43: =SUM(K41:K42) -> 0 | L43: =SUM(L41:L42) -> 0 | M43: =SUM(M41:M42) -> 0 | N43: =SUM(N41:N42) -> 0
G45: NOTA FISCAL | H45: VALOR BRUTO NF | I45: IR | J45: PIS | K45: COFINS | L45: CSLL | M45: ISS | N45: VALOR LIQUIDO
I46: =H46*4.8% -> 0 | J46: =H46*0.65% -> 0 | K46: =H46*3% -> 0 | L46: =H46*1% -> 0 | N46: =H46-I46-J46-K46-L46-M46 -> 0
I47: =H47*4.8% -> 0 | J47: =H47*0.65% -> 0 | K47: =H47*3% -> 0 | L47: =H47*1% -> 0 | N47: =H47-I47-J47-K47-L47-M47 -> 0
G48: TOTAL | H48: =SUM(H46:H47) -> 0 | I48: =SUM(I46:I47) -> 0 | J48: =SUM(J46:J47) -> 0 | K48: =SUM(K46:K47) -> 0 | L48: =SUM(L46:L47) -> 0 | M48: =SUM(M46:M47) -> 0 | N48: =SUM(N46:N47) -> 0

Sheet 28.07.26
A1: CONTA: 200000 AGÊNCIA: 3309
A3: SALDO INICIAL: | B3: ='27.07.26'!B33 -> 200007.3
A4: Recebimentos | B4: =SUM(B5:B54) -> 5509954.5 | C4: SITUAÇÃO | D4: NÚMERO DO RECEBIMENTO | E4: TIPO DE SERVIÇO | G4: NOTA FISCAL | H4: VALOR BRUTO NF | I4: IR | J4: PIS | K4: COFINS | L4: CSLL | M4: ISS | N4: VALOR LIQUIDO
A5: Recebimentos Diversos: 00.544.659/0001-09 BB-PREVIDENCIA FUND | B5: 3321.69 | C5: VALOR LANÇADO | D5: 2807001-GYN | E5: E-MAIL MARKETING BB | I5: =H5*4.8% -> 0 | J5: =H5*0.65% -> 0 | K5: =H5*3% -> 0 | L5: =H5*1% -> 0 | M5: =H5*5% -> 0 | N5: =H5-I5-J5-K5-L5-M5 -> 0
A6: Crédito Sistema CDA: Pgt.BB Con202574216943/0007 / 1 | B6: 3249770 | C6: VALOR LANÇADO | D6: 2807002-GYN | E6: FAB DESENV SOFT BB | I6: =H6*4.8% -> 0 | J6: =H6*0.65% -> 0 | K6: =H6*3% -> 0 | L6: =H6*1% -> 0 | M6: =H6*5% -> 0 | N6: =H6-I6-J6-K6-L6-M6 -> 0
A7: Crédito Sistema CDA: Pgt.BB Con202574216943/0007 / 2 | B7: 2256862.8 | C7: VALOR LANÇADO | D7: 2807003-GYN | E7: FAB DESENV SOFT BB | I7: =H7*4.8% -> 0 | J7: =H7*0.65% -> 0 | K7: =H7*3% -> 0 | L7: =H7*1% -> 0 | M7: =H7*5% -> 0 | N7: =H7-I7-J7-K7-L7-M7 -> 0
G8: TOTAL | H8: =SUM(H5:H7) -> 0 | I8: =SUM(I5:I7) -> 0 | J8: =SUM(J5:J7) -> 0 | K8: =SUM(K5:K7) -> 0 | L8: =SUM(L5:L7) -> 0 | M8: =SUM(M5:M7) -> 0 | N8: =SUM(N5:N7) -> 0
G10: NOTA FISCAL | H10: VALOR BRUTO NF | I10: IR | J10: PIS | K10: COFINS | L10: CSLL | M10: ISS | N10: VALOR LIQUIDO
I11: =H11*4.8% -> 0 | J11: =H11*0.65% -> 0 | K11: =H11*3% -> 0 | L11: =H11*1% -> 0 | M11: =H11*5% -> 0 | N11: =H11-I11-J11-K11-L11-M11 -> 0
I12: =H12*4.8% -> 0 | J12: =H12*0.65% -> 0 | K12: =H12*3% -> 0 | L12: =H12*1% -> 0 | M12: =H12*5% -> 0 | N12: =H12-I12-J12-K12-L12-M12 -> 0
I13: =H13*4.8% -> 0 | J13: =H13*0.65% -> 0 | K13: =H13*3% -> 0 | L13: =H13*1% -> 0 | M13: =H13*5% -> 0 | N13: =H13-I13-J13-K13-L13-M13 -> 0
I14: =H14*4.8% -> 0 | J14: =H14*0.65% -> 0 | K14: =H14*3% -> 0 | L14: =H14*1% -> 0 | M14: =H14*5% -> 0 | N14: =H14-I14-J14-K14-L14-M14 -> 0
G15: TOTAL | H15: =SUM(H11:H14) -> 0 | I15: =SUM(I11:I14) -> 0 | J15: =SUM(J11:J14) -> 0 | K15: =SUM(K11:K14) -> 0 | L15: =SUM(L11:L14) -> 0 | M15: =SUM(M11:M14) -> 0 | N15: =SUM(N11:N14) -> 0
G17: NOTA FISCAL | H17: VALOR BRUTO NF | I17: IR | J17: PIS | K17: COFINS | L17: CSLL | M17: ISS | N17: VALOR LIQUIDO
I18: =H18*1.5% -> 0 | N18: =H18-I18-J18-K18-L18-M18 -> 0
G19: TOTAL | H19: =SUM(H17:H18) -> 0 | I19: =SUM(I17:I18) -> 0 | J19: =SUM(J17:J18) -> 0 | K19: =SUM(K17:K18) -> 0 | L19: =SUM(L17:L18) -> 0 | M19: =SUM(M17:M18) -> 0 | N19: =SUM(N17:N18) -> 0
G21: NOTA FISCAL | H21: VALOR BRUTO NF | I21: IR | J21: PIS | K21: COFINS | L21: CSLL | M21: ISS | N21: VALOR LIQUIDO
I22: =H22*4.8% -> 0 | N22: =H22-I22-J22-K22-L22-M22 -> 0
G23: TOTAL | H23: =SUM(H21:H22) -> 0 | I23: =SUM(I21:I22) -> 0 | J23: =SUM(J21:J22) -> 0 | K23: =SUM(K21:K22) -> 0 | L23: =SUM(L21:L22) -> 0 | M23: =SUM(M21:M22) -> 0 | N23: =SUM(N21:N22) -> 0
G26: NOTA FISCAL | H26: VALOR BRUTO NF | I26: IR | J26: PIS | K26: COFINS | L26: CSLL | M26: ISS | N26: VALOR LIQUIDO
I27: =H27*4.8% -> 0 | J27: =H27*0.65% -> 0 | K27: =H27*3% -> 0 | L27: =H27*1% -> 0 | M27: 0 | N27: =H27-I27-J27-K27-L27-M27 -> 0
I28: =H28*4.8% -> 0 | J28: =H28*0.65% -> 0 | K28: =H28*3% -> 0 | L28: =H28*1% -> 0 | M28: 0 | N28: =H28-I28-J28-K28-L28-M28 -> 0
G29: TOTAL | H29: =SUM(H27:H28) -> 0 | I29: =SUM(I27:I28) -> 0 | J29: =SUM(J27:J28) -> 0 | K29: =SUM(K27:K28) -> 0 | L29: =SUM(L27:L28) -> 0 | M29: =SUM(M27:M28) -> 0 | N29: =SUM(N27:N28) -> 0
G31: NOTA FISCAL | H31: VALOR BRUTO NF | I31: IR | J31: PIS | K31: COFINS | L31: CSLL | M31: ISS | N31: VALOR LIQUIDO
I32: =H32*4.8% -> 0 | J32: =H32*0.65% -> 0 | K32: =H32*3% -> 0 | L32: =H32*1% -> 0 | M32: 0 | N32: =H32-I32-J32-K32-L32-M32 -> 0
G34: NOTA FISCAL | H34: VALOR BRUTO NF | I34: IR | J34: PIS | K34: COFINS | L34: CSLL | M34: ISS | N34: VALOR LIQUIDO
I35: =H35*4.8% -> 0 | J35: =H35*0.65% -> 0 | K35: =H35*3% -> 0 | L35: =H35*1% -> 0 | N35: =H35-I35-J35-K35-L35-M35 -> 0
G37: NOTA FISCAL | H37: VALOR BRUTO NF | I37: IR | J37: PIS | K37: COFINS | L37: CSLL | M37: ISS | N37: VALOR LIQUIDO
I38: =H38*4.8% -> 0 | J38: =H38*0.65% -> 0 | K38: =H38*3% -> 0 | L38: =H38*1% -> 0 | N38: =H38-I38-J38-K38-L38-M38 -> 0
G40: NOTA FISCAL | H40: VALOR BRUTO NF | I40: IR | J40: PIS | K40: COFINS | L40: CSLL | M40: ISS | N40: VALOR LIQUIDO
I41: =H41*4.8% -> 0 | J41: =H41*0.65% -> 0 | K41: =H41*3% -> 0 | L41: =H41*1% -> 0 | N41: =H41-I41-J41-K41-L41-M41 -> 0
G52: NOTA FISCAL | H52: VALOR BRUTO NF | I52: IR 1,5% | J52: VALOR LIQUIDO
G53: 86 | H53: 3913939.6 | I53: =H53*1.5% -> 58709.094 | J53: =H53-I53 -> 3855230.5
A55: Pagamentos | B55: =SUM(B56:B68) -> 0 | C55: SITUAÇÃO | D55: NÚMERO DO RECEBIMENTO | E55: TIPO DE SERVIÇO
A69: SALDO FINAL: | B69: =B3+B4-B55 -> 5709961.8

Sheet 29.07.26
A1: CONTA: 200000 AGÊNCIA: 3309
C2: %2000% | D2: 46232
A3: SALDO INICIAL: | B3: ='28.07.26'!B69 -> 5709961.8
A4: Recebimentos | B4: =SUM(B5:B49) -> 69479550 | C4: SITUAÇÃO | D4: NÚMERO DO RECEBIMENTO | E4: TIPO DE SERVIÇO | G4: NOTA FISCAL | H4: VALOR BRUTO NF | I4: IR | J4: PIS | K4: COFINS | L4: CSLL | M4: ISS | N4: VALOR LIQUIDO | O4: RECEBIMENTO DE MULTAS FORNEC. | P4: VALOR LIQUIDO RECEBIDO
A5: Crédito Sistema CDA: Pgt.BB Con202185580061/0062 / 1 | B5: 695976.44 | C5: VALOR LANÇADO | D5: 2907001-GYN | E5: MANUT PROGR COMPUT | G5: 42 | H5: 1319024.8 | I5: =H5*4.8% -> 63313.19 | J5: =H5*0.65% -> 8573.6612 | K5: =H5*3% -> 39570.744 | L5: =H5*1% -> 13190.248 | N5: =H5-I5-J5-K5-L5-M5 -> 1194377
A6: Crédito Sistema CDA: Pgt.BB Con202185580038/0070 / 1 | B6: 263453.53 | C6: VALOR LANÇADO | D6: 2907002-GYN | E6: MONITORA AMBIENTE BB | G6: 113 | H6: 6689782.7 | I6: =H6*4.8% -> 321109.57 | J6: =H6*0.65% -> 43483.588 | K6: =H6*3% -> 200693.48 | L6: =H6*1% -> 66897.827 | N6: =H6-I6-J6-K6-L6-M6 -> 6057598.3
A7: Crédito Sistema CDA: Pgt.BB Con202274213769/0052 / 1 | B7: 3956976.3 | C7: VALOR LANÇADO | D7: 2907003-GYN | E7: SUP TEC SW LICENTER | G7: TOTAL | H7: =SUM(H5:H6) -> 8008807.5 | I7: =SUM(I5:I6) -> 384422.76 | J7: =SUM(J5:J6) -> 52057.249 | K7: =SUM(K5:K6) -> 240264.23 | L7: =SUM(L5:L6) -> 80088.075 | M7: =SUM(M5:M6) -> 0 | N7: =SUM(N5:N6) -> 7251975.2 | O7: 101524.15 | P7: =N7-O7 -> 7150451.1
A8: Crédito Sistema CDA: PAGTO.BB CONVENIO COOPERATIVA | B8: 6035808.4 | C8: VALOR LANÇADO | D8: 2907004-GYN | E8: CORRESPOND BANCARIO
A9: Crédito Sistema CDA: PAGTO.BB DEMAIS DESP.OPER./CORRESPONDE | B9: 1127689.8 | C9: VALOR LANÇADO | D9: 2907005-GYN | E9: CORRESPOND BANCARIO | K9: 101524.16 | N9: 7150451.1
A10: Crédito Sistema CDA: PAGTO.BB CONVENIO COOPERATIVA | B10: 11905177 | C10: VALOR LANÇADO | D10: 2907006-GYN | E10: CORRESPOND BANCARIO
A11: Crédito Sistema CDA: PAGTO.BB CONTA CORRENTE COM COMPULSORI | B11: 5543.32 | C11: VALOR LANÇADO | D11: 2907007-GYN | E11: CORRESPOND BANCARIO | N11: =N7-N9 -> 101524.16
A12: Crédito Sistema CDA: PAGTO.BB CREDITO IMOBILIARIO PMCMV AQU | B12: 698631.38 | C12: VALOR LANÇADO | D12: 2907008-GYN | E12: CORRESPOND BANCARIO | G12: NOTA FISCAL | H12: VALOR BRUTO NF | I12: IR | J12: PIS | K12: COFINS | L12: CSLL | M12: ISS | N12: VALOR LIQUIDO
A13: Crédito Sistema CDA: PAGTO.BB DEMAIS DESP.OPER./CORRESPONDE | B13: 27.16 | C13: VALOR LANÇADO | D13: 2907009-GYN | E13: CORRESPOND BANCARIO | G13: 122 | H13: 30 | I13: =H13*4.8% -> 1.44 | J13: =H13*0.65% -> 0.195 | K13: =H13*3% -> 0.9 | L13: =H13*1% -> 0.3 | N13: =H13-I13-J13-K13-L13-M13 -> 27.165
A14: Crédito Sistema CDA: PAGTO.BB BB CREDITO CONSIGNACAO - NAO | B14: 296574.6 | C14: VALOR LANÇADO | D14: 2907010-GYN | E14: FATURAMENTO REPASSE
A15: Crédito Sistema CDA: PAGTO.BB CREDITO IMOBILIARIO PMCMV AQU | B15: 428700.95 | C15: VALOR LANÇADO | D15: 2907011-GYN | E15: FATURAMENTO REPASSE | G15: NOTA FISCAL | H15: VALOR BRUTO NF | I15: IR | J15: PIS | K15: COFINS | L15: CSLL | M15: ISS | N15: VALOR LIQUIDO
A16: Crédito Sistema CDA: PAGTO.BB DEMAIS DESP.OPER./CORRESPONDE | B16: 34830.33 | C16: VALOR LANÇADO | D16: 2907012-GYN | E16: CORRESPOND BANCARIO | G16: 126 | H16: 38106.97 | I16: =H16*4.8% -> 1829.1346 | J16: =H16*0.65% -> 247.69531 | K16: =H16*3% -> 1143.2091 | L16: =H16*1% -> 381.0697 | N16: =H16-I16-J16-K16-L16-M16 -> 34505.861
A17: Crédito Sistema CDA: Pgt.BB Con202685580039/0002 / 1 | B17: 2956262.6 | C17: VALOR LANÇADO | D17: 2907013-GYN | E17: MANUT TAA BB | G17: 3173 | H17: 388.72 | I17: =H17*4.8% -> 18.65856 | J17: =H17*0.65% -> 2.52668 | K17: =H17*3% -> 11.6616 | L17: =H17*1% -> 3.8872 | M17: 27.52 | N17: =H17-I17-J17-K17-L17-M17 -> 324.46596
A18: Crédito Sistema CDA: Pgt.BB Con202685580039/0002 / 2 | B18: 2346959.6 | C18: VALOR LANÇADO | D18: 2907014-GYN | E18: MANUT TAA BB | G18: TOTAL | H18: =SUM(H16:H17) -> 38495.69 | I18: =SUM(I16:I17) -> 1847.7931 | J18: =SUM(J16:J17) -> 250.22199 | K18: =SUM(K16:K17) -> 1154.8707 | L18: =SUM(L16:L17) -> 384.9569 | M18: =SUM(M16:M17) -> 27.52 | N18: =SUM(N16:N17) -> 34830.327
A19: Crédito Sistema CDA: Pgt.BB Con202685580039/0002 / 3 | B19: 1016519.9 | C19: VALOR LANÇADO | D19: 2907015-GYN | E19: MANUT TAA BB
A20: Crédito Sistema CDA: Pgt.BB Con202685580039/0002 / 4 | B20: 1489735.2 | C20: VALOR LANÇADO | D20: 2907016-GYN | E20: MANUT TAA BB | G20: NOTA FISCAL | H20: VALOR BRUTO NF | I20: IR | J20: PIS | K20: COFINS | L20: CSLL | M20: ISS | N20: VALOR LIQUIDO
A21: Crédito Sistema CDA: Pgt.BB Con202685580039/0002 / 5 | B21: 1524077.2 | C21: VALOR LANÇADO | D21: 2907017-GYN | E21: MANUT TAA BB | G21: 121 | H21: 6647019.8 | I21: =H21*4.8% -> 319056.95 | J21: =H21*0.65% -> 43205.629 | K21: =H21*3% -> 199410.59 | L21: =H21*1% -> 66470.198 | M21: 2519.9435 | N21: =H21-I21-J21-K21-L21-M21 -> 6016356.5
A22: Crédito Sistema CDA: Pgt.BB Con202685580039/0002 / 6 | B22: 743338.42 | C22: VALOR LANÇADO | D22: 2907018-GYN | E22: MANUT TAA BB | G22: 3169 | H22: 22737.53 | I22: =H22*4.8% -> 1091.4014 | J22: =H22*0.65% -> 147.79395 | K22: =H22*3% -> 682.1259 | L22: =H22*1% -> 227.3753 | M22: =H22*5% -> 1136.8765 | N22: =H22-I22-J22-K22-L22-M22 -> 19451.957
A23: Crédito Sistema CDA: Pgt.BB Con202685580039/0002 / 7 | B23: 857939.17 | C23: VALOR LANÇADO | D23: 2907019-GYN | E23: MANUT TAA BB | G23: TOTAL | H23: =SUM(H21:H22) -> 6669757.3 | I23: =SUM(I21:I22) -> 320148.35 | J23: =SUM(J21:J22) -> 43353.423 | K23: =SUM(K21:K22) -> 200092.72 | L23: =SUM(L21:L22) -> 66697.573 | M23: =SUM(M21:M22) -> 3656.82 | N23: =SUM(N21:N22) -> 6035808.4
A24: Crédito Sistema CDA: Pgt.BB Con202685580039/0002 / 8 | B24: 1353481.9 | C24: VALOR LANÇADO | D24: 2907020-GYN | E24: MANUT TAA BB
A25: Crédito Sistema CDA: Pgt.BB Con202685580039/0002 / 9 | B25: 744748.57 | C25: VALOR LANÇADO | D25: 2907021-GYN | E25: MANUT TAA BB | G25: NOTA FISCAL | H25: VALOR BRUTO NF | I25: IR | J25: PIS | K25: COFINS | L25: CSLL | M25: ISS | N25: VALOR LIQUIDO
A26: Crédito Sistema CDA: Pgt.BB Con202685580039/0002 / 10 | B26: 1363498.2 | C26: VALOR LANÇADO | D26: 2907022-GYN | E26: MANUT TAA BB | G26: 120 | H26: 13126597 | I26: =H26*4.8% -> 630076.66 | J26: =H26*0.65% -> 85322.881 | K26: =H26*3% -> 393797.91 | L26: =H26*1% -> 131265.97 | M26: 1966.406 | N26: =H26-I26-J26-K26-L26-M26 -> 11884167
A27: Crédito Sistema CDA: Pgt.BB Con202685580039/0002 / 11 | B27: 1096674.7 | C27: VALOR LANÇADO | D27: 2907023-GYN | E27: MANUT TAA BB | G27: 3168 | H27: 24558.08 | I27: =H27*4.8% -> 1178.7878 | J27: =H27*0.65% -> 159.62752 | K27: =H27*3% -> 736.7424 | L27: =H27*1% -> 245.5808 | M27: =H27*5% -> 1227.904 | N27: =H27-I27-J27-K27-L27-M27 -> 21009.437
A28: Crédito Sistema CDA: Pgt.BB Con202685580039/0002 / 12 | B28: 1237479.4 | C28: VALOR LANÇADO | D28: 2907024-GYN | E28: MANUT TAA BB | G28: TOTAL | H28: =SUM(H26:H27) -> 13151155 | I28: =SUM(I26:I27) -> 631255.45 | J28: =SUM(J26:J27) -> 85482.509 | K28: =SUM(K26:K27) -> 394534.66 | L28: =SUM(L26:L27) -> 131511.55 | M28: =SUM(M26:M27) -> 3194.31 | N28: =SUM(N26:N27) -> 11905177
A29: Crédito Sistema CDA: Pgt.BB Con202685580039/0002 / 13 | B29: 726951.42 | C29: VALOR LANÇADO | D29: 2907025-GYN | E29: MANUT TAA BB
A30: Crédito Sistema CDA: Pgt.BB Con202685580039/0002 / 14 | B30: 899341.36 | C30: VALOR LANÇADO | D30: 2907026-GYN | E30: MANUT TAA BB | G30: NOTA FISCAL | H30: VALOR BRUTO NF | I30: IR | J30: PIS | K30: COFINS | L30: CSLL | M30: ISS | N30: VALOR LIQUIDO
A31: Crédito Sistema CDA: Pgt.BB Con202685580039/0002 / 15 | B31: 997810.15 | C31: VALOR LANÇADO | D31: 2907027-GYN | E31: MANUT TAA BB | G31: 125 | H31: 5670 | I31: =H31*4.8% -> 272.16 | J31: =H31*0.65% -> 36.855 | K31: =H31*3% -> 170.1 | L31: =H31*1% -> 56.7 | M31: 1.5 | N31: =H31-I31-J31-K31-L31-M31 -> 5132.685
A32: Crédito Sistema CDA: Pgt.BB Con202685580039/0002 / 16 | B32: 401883.56 | C32: VALOR LANÇADO | D32: 2907028-GYN | E32: MANUT TAA BB | G32: 3172 | H32: 480 | I32: =H32*4.8% -> 23.04 | J32: =H32*0.65% -> 3.12 | K32: =H32*3% -> 14.4 | L32: =H32*1% -> 4.8 | M32: =H32*5% -> 24 | N32: =H32-I32-J32-K32-L32-M32 -> 410.64
A33: Crédito Sistema CDA: Pgt.BB Con202685580039/0002 / 17 | B33: 694364.4 | C33: VALOR LANÇADO | D33: 2907029-GYN | E33: MANUT TAA BB | G33: TOTAL | H33: =SUM(H31:H32) -> 6150 | I33: =SUM(I31:I32) -> 295.2 | J33: =SUM(J31:J32) -> 39.975 | K33: =SUM(K31:K32) -> 184.5 | L33: =SUM(L31:L32) -> 61.5 | M33: =SUM(M31:M32) -> 25.5 | N33: =SUM(N31:N32) -> 5543.325
A34: Crédito Sistema CDA: Pgt.BB Con202685580039/0002 / 18 | B34: 926854.2 | C34: VALOR LANÇADO | D34: 2907030-GYN | E34: MANUT TAA BB
A35: Crédito Sistema CDA: Pgt.BB Con202685580039/0002 / 19 | B35: 1277586.1 | C35: VALOR LANÇADO | D35: 2907031-GYN | E35: MANUT TAA BB | G35: NOTA FISCAL | H35: VALOR BRUTO NF | I35: IR | J35: PIS | K35: COFINS | L35: CSLL | M35: ISS | N35: VALOR LIQUIDO
A36: Crédito Sistema CDA: Pgt.BB Con202685580039/0002 / 20 | B36: 573693.51 | C36: VALOR LANÇADO | D36: 2907032-GYN | E36: MANUT TAA BB | G36: 124 | H36: 729542.22 | I36: =H36*4.8% -> 35018.027 | J36: =H36*0.65% -> 4742.0244 | K36: =H36*3% -> 21886.267 | L36: =H36*1% -> 7295.4222 | M36: 1168.497 | N36: =H36-I36-J36-K36-L36-M36 -> 659431.98
A37: Crédito Sistema CDA: Pgt.BB Con202685580039/0002 / 21 | B37: 621045.16 | C37: VALOR LANÇADO | D37: 2907033-GYN | E37: MANUT TAA BB | G37: 3171 | H37: 45820.46 | I37: =H37*4.8% -> 2199.3821 | J37: =H37*0.65% -> 297.83299 | K37: =H37*3% -> 1374.6138 | L37: =H37*1% -> 458.2046 | M37: =H37*5% -> 2291.023 | N37: =H37-I37-J37-K37-L37-M37 -> 39199.404
A38: Crédito Sistema CDA: Pgt.BB Con202685580039/0002 / 22 | B38: 1352517.5 | C38: VALOR LANÇADO | D38: 2907034-GYN | E38: MANUT TAA BB | G38: TOTAL | H38: =SUM(H36:H37) -> 775362.68 | I38: =SUM(I36:I37) -> 37217.409 | J38: =SUM(J36:J37) -> 5039.8574 | K38: =SUM(K36:K37) -> 23260.88 | L38: =SUM(L36:L37) -> 7753.6268 | M38: =SUM(M36:M37) -> 3459.52 | N38: =SUM(N36:N37) -> 698631.39
A39: Crédito Sistema CDA: Pgt.BB Con202685580039/0002 / 23 | B39: 2370089.3 | C39: VALOR LANÇADO | D39: 2907035-GYN | E39: MANUT TAA BB
A40: Crédito Sistema CDA: Pgt.BB Con202685580039/0002 / 24 | B40: 953200.7 | C40: VALOR LANÇADO | D40: 2907036-GYN | E40: MANUT TAA BB | G40: NOTA FISCAL | H40: VALOR BRUTO NF | I40: IR | J40: PIS | K40: COFINS | L40: CSLL | M40: ISS | N40: VALOR LIQUIDO
...

Sheet 30.07.26
A1: CONTA: 200000 AGÊNCIA: 3309
A3: SALDO INICIAL: | B3: ='29.07.26'!B64 -> 69679558
A4: Recebimentos | B4: =SUM(B5:B11) -> 0 | C4: SITUAÇÃO | D4: NÚMERO DO RECEBIMENTO | E4: TIPO DE SERVIÇO | G4: NOTA FISCAL | H4: VALOR BRUTO NF | I4: IR | J4: PIS | K4: COFINS | L4: CSLL | M4: ISS | N4: VALOR LIQUIDO
I5: =H5*4.8% -> 0 | J5: =H5*0.65% -> 0 | K5: =H5*3% -> 0 | L5: =H5*1% -> 0 | N5: =H5-I5-J5-K5-L5-M5 -> 0
A12: Pagamentos | B12: =SUM(B13:B25) -> 69588088 | C12: SITUAÇÃO | D12: NÚMERO DO RECEBIMENTO | E12: TIPO DE SERVIÇO
A13: Transferência enviada: 553.309.000.205.826 30/07 10:16 BB TEC 00042318949000184 | B13: 69479549 | C13: VALOR LANÇADO | E13: TRANSFERÊNCIA
A14: Retenção IOF a Recolher | B14: 3132.85 | C14: VALOR LANÇADO | E14: TRANSFERÊNCIAS
A15: Câmbio | B15: 89510.13 | C15: VALOR LANÇADO | E15: TRANSFERÊNCIAS
A16: Retenção Imposto de Renda | B16: 15894.97 | C16: VALOR LANÇADO | E16: TRANSFERÊNCIAS
A17: Tarifa Transf Recurso-E/I: Cobrança referente 30/07/2026 | B17: 1.7 | C17: VALOR LANÇADO | D17: 30-JUL-26001001200000/5 | E17: TARIFAS
A26: SALDO FINAL: | B26: =B3+B4-B12 -> 91469.35
G37: NOTA FISCAL | H37: VALOR BRUTO NF | I37: IR 1,5% | J37: VALOR LIQUIDO
G38: 86 | H38: 3913939.6 | I38: =H38*1.5% -> 58709.094 | J38: =H38-I38 -> 3855230.5

Sheet 31.07.26
A1: CONTA: 200000 AGÊNCIA: 3309
A3: SALDO INICIAL: | B3: ='30.07.26'!B26 -> 91469.35
A4: Recebimentos | B4: =SUM(B5:B11) -> 123966.6 | C4: SITUAÇÃO | D4: NÚMERO DO RECEBIMENTO | E4: TIPO DE SERVIÇO | G4: NOTA FISCAL | H4: VALOR BRUTO NF | I4: IR 1,5% | J4: VALOR LIQUIDO
A5: Transferência recebida 613.309.000.205.826 31/07 09:47 BB TECNOLOGIA E SERVICOS | B5: 108539.65 | C5: VALOR LANÇADO | E5: TRANSFERÊNCIA | G5: 115 | H5: 15661.88 | I5: =H5*1.5% -> 234.9282 | J5: =H5-I5 -> 15426.952
A6: Recebimento Fornecedor: 27.833.136/0001-39 BB CORRETORA DE SEG | B6: 15426.95 | C6: VALOR LANÇADO | D6: 3107001-GYN | E6: PRODUTOS SEGURIDADE
A12: Pagamentos | B12: =SUM(B13:B25) -> 0 | C12: SITUAÇÃO | D12: NÚMERO DO RECEBIMENTO | E12: TIPO DE SERVIÇO
A26: SALDO FINAL: | B26: =B3+B4-B12 -> 215435.95

Sheet 27.02.26
A1: CONTA: 200000 AGÊNCIA: 3309
A3: SALDO INICIAL: | B3: ='27.07.26'!B33 -> 200007.3
A4: Recebimentos | B4: =SUM(B5:B55) -> 16501795 | C4: SITUAÇÃO | D4: NÚMERO DO RECEBIMENTO | E4: TIPO DE SERVIÇO | G4: NOTA FISCAL | H4: VALOR BRUTO NF | I4: ISS 5% | J4: VALOR LIQUIDO
G5: 2765 | H5: 6762.8 | I5: =H5*5% -> 338.14 | J5: =H5-I5 -> 6424.66
A16: Crédito Sistema CDA: Pgt.BB Con202185580050/0054 / 9 | B16: 1233893.2 | C16: VALOR LANÇADO | D16: 2702012-GYN | E16: MANUT TAA BB
A17: Crédito Sistema CDA: Pgt.BB Con202185580050/0054 / 10 | B17: 952157.16 | C17: VALOR LANÇADO | D17: 2702013-GYN | E17: MANUT TAA BB
A18: Crédito Sistema CDA: Pgt.BB Con202185580050/0054 / 11 | B18: 1305547.9 | C18: VALOR LANÇADO | D18: 2702014-GYN | E18: MANUT TAA BB
A19: Crédito Sistema CDA: Pgt.BB Con202185580050/0054 / 12 | B19: 684450.52 | C19: VALOR LANÇADO | D19: 2702015-GYN | E19: MANUT TAA BB
A28: Crédito Sistema CDA: Pgt.BB Con202185580050/0054 / 21 | B28: 550006.18 | C28: VALOR LANÇADO | D28: 2702024-GYN | E28: MANUT TAA BB
A29: Crédito Sistema CDA: Pgt.BB Con202185580050/0054 / 22 | B29: 1207313 | C29: VALOR LANÇADO | D29: 2702025-GYN | E29: MANUT TAA BB | F29: x
A30: Crédito Sistema CDA: Pgt.BB Con202185580050/0054 / 23 | B30: 1978239 | C30: VALOR LANÇADO | D30: 2702026-GYN | E30: MANUT TAA BB
A31: Crédito Sistema CDA: Pgt.BB Con202185580050/0054 / 24 | B31: 2051430.4 | C31: VALOR LANÇADO | D31: 2702027-GYN | E31: MANUT TAA BB
A32: Crédito Sistema CDA: Pgt.BB Con202185580050/0054 / 25 | B32: 864125.47 | C32: VALOR LANÇADO | D32: 2702028-GYN | E32: MANUT TAA BB
A33: Crédito Sistema CDA: Pgt.BB Con202185580050/0054 / 26 | B33: 2175383.2 | C33: VALOR LANÇADO | D33: 2702029-GYN | E33: MANUT TAA BB
A34: Crédito Sistema CDA: Pgt.BB Con202185580050/0054 / 27 | B34: 669720.28 | C34: VALOR LANÇADO | D34: 2702030-GYN | E34: MANUT TAA BB
A35: Crédito Sistema CDA: Pgt.BB Con202185580050/0054 / 28 | B35: 1284245.3 | C35: VALOR LANÇADO | D35: 2702031-GYN | E35: MANUT TAA BB
A36: Crédito Sistema CDA: Pgt.BB Con202185580050/0054 / 29 | B36: 586933.33 | C36: VALOR LANÇADO | D36: 2702032-GYN | E36: MANUT TAA BB | F36: X | G36: Dia incorreto
A37: Crédito Sistema CDA: Pgt.BB Con202185580050/0054 / 30 | B37: 767588.98 | C37: VALOR LANÇADO | D37: 2702033-GYN | E37: MANUT TAA BB | F37: X | G37: Dia incorreto
A38: Crédito Sistema CDA: Pgt.BB Con202185580050/0054 / 31 | B38: 184291.82 | C38: VALOR LANÇADO | D38: 2702034-GYN | E38: MANUT TAA BB | F38: X | G38: Dia incorreto | H38: Corrigido
A39: Devolução ISSQN Retido | B39: 43.46 | C39: VALOR LANÇADO | D39: 2702035-GYN | E39: DEVOLUCAO DE ISS CLIENTES
A40: Devolução ISSQN Retido | B40: 0.91 | C40: VALOR LANÇADO | D40: 2702036-GYN | E40: DEVOLUCAO DE ISS CLIENTES
A41: Recebimentos Diversos: 05.437.257/0001-29 ATIVOS S.A. SECURIT | B41: 6424.66 | C41: VALOR LANÇADO | D41: 2702037-GYN | E41: SOLUCAO HIVEPLACE
A56: Pagamentos | B56: =SUM(B57:B69) -> 37943611 | C56: SITUAÇÃO | D56: NÚMERO DO RECEBIMENTO | E56: TIPO DE SERVIÇO
A57: Transferência enviada: 553.309.000.205.826 27/02 11:04 BB TEC 00042318949000184 | B57: 37943609 | C57: VALOR LANÇADO | E57: TRANSFERÊNCIAS
A58: Tarifa Transf Recurso-E/I: Cobrança referente 27/02/2026 | B58: 1.7 | C58: VALOR LANÇADO | D58: 27-FEV-26001001200000/39 | E58: TARIFAS
A70: SALDO FINAL: | B70: =B3+B4-B56 -> -21241809

Sheet Penultimo dia 
A1: CONTA: 200000 AGÊNCIA: 3309
A3: SALDO INICIAL: | B3: =#REF! -> #REF!
A4: Recebimentos | B4: =SUM(B5:B18) -> 0 | C4: SITUAÇÃO | D4: TIPO DE SERVIÇO
A19: Pagamentos | B19: =SUM(B20:B32) -> 0 | C19: SITUAÇÃO | D19: TIPO DE SERVIÇO
A33: SALDO FINAL: | B33: =B3+B4-B19 -> #REF!

Sheet Ultimo dia 
A1: CONTA: 200000 AGÊNCIA: 3309
